<mujoco model="unnamed_model">
  <compiler autolimits="true" angle="radian"/>
  <option impratio="10" cone="elliptic"/>
  <default>
    <default class="/"/>
    <default class="vx300s/">
      <default class="vx300s/vx300s">
        <joint axis="0 1 0"/>
        <position forcerange="-35 35"/>
        <default class="vx300s/waist">
          <joint axis="0 0 1" range="-3.1415799999999998 3.1415799999999998" damping="2.8599999999999999"/>
          <position ctrlrange="-3.1415799999999998 3.1415799999999998" kp="25"/>
        </default>
        <default class="vx300s/shoulder">
          <joint range="-1.85005 1.25664" armature="0.0040000000000000001" damping="6.25" frictionloss="0.059999999999999998"/>
          <position ctrlrange="-1.85005 1.25664" forcerange="-57 57" kp="76"/>
        </default>
        <default class="vx300s/elbow">
          <joint range="-1.76278 1.6056999999999999" armature="0.071999999999999995" damping="8.1500000000000004" frictionloss="1.74"/>
          <position ctrlrange="-1.76278 1.6056999999999999" forcerange="-25 25" kp="106"/>
        </default>
        <default class="vx300s/forearm_roll">
          <joint axis="1 0 0" range="-3.1415799999999998 3.1415799999999998" armature="0.059999999999999998" damping="3.0699999999999998"/>
          <position ctrlrange="-3.1415799999999998 3.1415799999999998" forcerange="-10 10" kp="35"/>
        </default>
        <default class="vx300s/wrist_angle">
          <joint range="-1.8674999999999999 2.2340200000000001" damping="1.1799999999999999"/>
          <position ctrlrange="-1.8674999999999999 2.2340200000000001" kp="8"/>
        </default>
        <default class="vx300s/wrist_rotate">
          <joint axis="1 0 0" range="-3.1415799999999998 3.1415799999999998" damping="0.78000000000000003"/>
          <position ctrlrange="-3.1415799999999998 3.1415799999999998" kp="7"/>
        </default>
        <default class="vx300s/finger">
          <joint type="slide" armature="0.251" damping="10"/>
          <position ctrlrange="0.021000000000000001 0.057000000000000002" kp="300"/>
          <default class="vx300s/left_finger">
            <joint range="0.021000000000000001 0.057000000000000002"/>
          </default>
          <default class="vx300s/right_finger">
            <joint range="-0.057000000000000002 -0.021000000000000001"/>
          </default>
        </default>
        <default class="vx300s/visual">
          <geom type="mesh" contype="0" conaffinity="0" group="2" material="vx300s/black" density="0"/>
        </default>
        <default class="vx300s/collision">
          <geom type="mesh" group="3"/>
          <default class="vx300s/finger_collision">
            <geom condim="4" friction="1 0.0050000000000000001 0.0001" solref="0.01 1" solimp="2 1 0.01"/>
          </default>
        </default>
      </default>
    </default>
  </default>
  <asset>
    <texture name="vx300s/interbotix_black" type="2d" file="interbotix_black-69c57550bd2feab175e72976e270d0619497e947.png"/>
    <material name="vx300s/black" class="vx300s/" texture="vx300s/interbotix_black"/>
    <mesh name="vx300s/vx300s_1_base" class="vx300s/" file="vx300s_1_base-8911efddeb54716caf91218e0beee848e0083aad.stl" scale="0.001 0.001 0.001"/>
    <mesh name="vx300s/vx300s_2_shoulder" class="vx300s/" file="vx300s_2_shoulder-5dee3af162e071b59ae35b1b7279fe257c375ffb.stl" scale="0.001 0.001 0.001"/>
    <mesh name="vx300s/vx300s_3_upper_arm" class="vx300s/" file="vx300s_3_upper_arm-f0b3692a22ad52ba9b3c439033c552c51222ed28.stl" scale="0.001 0.001 0.001"/>
    <mesh name="vx300s/vx300s_4_upper_forearm" class="vx300s/" file="vx300s_4_upper_forearm-6d4b69653fd0cc02e83bb7d65ba3e7ec1604b71c.stl" scale="0.001 0.001 0.001"/>
    <mesh name="vx300s/vx300s_5_lower_forearm" class="vx300s/" file="vx300s_5_lower_forearm-8555d345ad2564df22bcbd24557f5a69d362ef68.stl" scale="0.001 0.001 0.001"/>
    <mesh name="vx300s/vx300s_6_wrist" class="vx300s/" file="vx300s_6_wrist-b3facdc0498ab0119fb164f573de994a27c7401e.stl" scale="0.001 0.001 0.001"/>
    <mesh name="vx300s/vx300s_7_gripper" class="vx300s/" file="vx300s_7_gripper-b813b91c65958cecc40a079a3695cca6a9a2f192.stl" scale="0.001 0.001 0.001"/>
    <mesh name="vx300s/vx300s_8_gripper_prop" class="vx300s/" file="vx300s_8_gripper_prop-2868356f653644808fad6ba95e7aa086ed1503ab.stl" scale="0.001 0.001 0.001"/>
    <mesh name="vx300s/vx300s_9_gripper_bar" class="vx300s/" file="vx300s_9_gripper_bar-d8eb5f7b762882495079e8fc16086e4b14a5ea90.stl" scale="0.001 0.001 0.001"/>
    <mesh name="vx300s/vx300s_10_gripper_finger" class="vx300s/" file="vx300s_10_gripper_finger-9ac18da385ee1ddfff29a4f5ab33a0e819ea216e.stl" scale="0.001 0.001 0.001"/>
  </asset>
  <worldbody>
    <body name="vx300s/">
      <light name="vx300s//unnamed_light_0" class="vx300s/" mode="targetbodycom" target="vx300s/gripper_link" pos="1 0 1"/>
      <body name="vx300s/base_link" childclass="vx300s/vx300s">
        <inertial pos="-0.053477400000000001 -0.00056257500000000005 0.020596099999999999" quat="-0.0029232400000000001 0.71251699999999996 0.00480387 0.70163299999999995" mass="0.96903399999999995" diaginertia="0.0071633 0.0060245100000000003 0.00169819"/>
        <geom name="vx300s//unnamed_geom_0" class="vx300s/visual" quat="1 0 0 1" mesh="vx300s/vx300s_1_base"/>
        <geom name="vx300s//unnamed_geom_1" class="vx300s/collision" quat="1 0 0 1" mesh="vx300s/vx300s_1_base"/>
        <body name="vx300s/shoulder_link" pos="0 0 0.079000000000000001">
          <inertial pos="0.00025923299999999999 -3.3552000000000001e-06 0.011612900000000001" quat="-0.47611900000000001 0.47608299999999998 0.52278999999999998 0.52282600000000001" mass="0.79861400000000005" diaginertia="0.00120156 0.00113744 0.00093880000000000005"/>
          <joint name="vx300s/waist" class="vx300s/waist"/>
          <geom name="vx300s//unnamed_geom_2" class="vx300s/visual" pos="0 0 -0.0030000000000000001" quat="1 0 0 1" mesh="vx300s/vx300s_2_shoulder"/>
          <geom name="vx300s//unnamed_geom_3" class="vx300s/collision" pos="0 0 -0.0030000000000000001" quat="1 0 0 1" mesh="vx300s/vx300s_2_shoulder"/>
          <body name="vx300s/upper_arm_link" pos="0 0 0.048050000000000002">
            <inertial pos="0.020694899999999999 4.0000000000000001e-10 0.22645899999999999" quat="0 0.072845800000000002 0 0.99734299999999998" mass="0.79259199999999996" diaginertia="0.0091133800000000008 0.0089250000000000006 0.00075931700000000002"/>
            <joint name="vx300s/shoulder" class="vx300s/shoulder"/>
            <geom name="vx300s//unnamed_geom_4" class="vx300s/visual" quat="1 0 0 1" mesh="vx300s/vx300s_3_upper_arm"/>
            <geom name="vx300s//unnamed_geom_5" class="vx300s/collision" quat="1 0 0 1" mesh="vx300s/vx300s_3_upper_arm"/>
            <body name="vx300s/upper_forearm_link" pos="0.059549999999999999 0 0.29999999999999999">
              <inertial pos="0.105723 0 0" quat="-0.00062163099999999998 0.70472400000000002 0.010529200000000001 0.70940300000000001" mass="0.32222800000000001" diaginertia="0.00144107 0.0013422799999999999 0.00015204699999999999"/>
              <joint name="vx300s/elbow" class="vx300s/elbow"/>
              <geom name="vx300s//unnamed_geom_6" class="vx300s/visual" mesh="vx300s/vx300s_4_upper_forearm"/>
              <geom name="vx300s//unnamed_geom_7" class="vx300s/collision" mesh="vx300s/vx300s_4_upper_forearm"/>
              <body name="vx300s/lower_forearm_link" pos="0.20000000000000001 0 0">
                <inertial pos="0.051347700000000003 0.0068046199999999999 0" quat="-0.70260400000000001 -0.079672400000000004 -0.70260400000000001 0.079672400000000004" mass="0.414823" diaginertia="0.0005911 0.000546493 0.00015570699999999999"/>
                <joint name="vx300s/forearm_roll" class="vx300s/forearm_roll"/>
                <geom name="vx300s//unnamed_geom_8" class="vx300s/visual" quat="0 1 0 0" mesh="vx300s/vx300s_5_lower_forearm"/>
                <geom name="vx300s//unnamed_geom_9" class="vx300s/collision" quat="0 1 0 0" mesh="vx300s/vx300s_5_lower_forearm"/>
                <body name="vx300s/wrist_link" pos="0.10000000000000001 0 0">
                  <inertial pos="0.046743 -7.6652000000000007e-06 0.010565" quat="-0.00100191 0.54458600000000001 0.0026583000000000002 0.8387" mass="0.115395" diaginertia="5.4570700000000003e-05 4.6310100000000002e-05 4.3269200000000002e-05"/>
                  <joint name="vx300s/wrist_angle" class="vx300s/wrist_angle"/>
                  <geom name="vx300s//unnamed_geom_10" class="vx300s/visual" quat="1 0 0 1" mesh="vx300s/vx300s_6_wrist"/>
                  <geom name="vx300s//unnamed_geom_11" class="vx300s/collision" quat="1 0 0 1" mesh="vx300s/vx300s_6_wrist"/>
                  <body name="vx300s/gripper_link" pos="0.069744 0 0">
                    <inertial pos="0.039566200000000003 -2.5631100000000002e-07 0.0040064899999999997" quat="0.62033000000000005 0.61991600000000002 -0.33968199999999998 0.33986899999999998" mass="0.25165199999999999" diaginertia="0.00068954599999999997 0.00065031599999999996 0.000468142"/>
                    <joint name="vx300s/wrist_rotate" class="vx300s/wrist_rotate"/>
                    <geom name="vx300s//unnamed_geom_12" class="vx300s/visual" pos="-0.02 0 0" quat="1 0 0 1" mesh="vx300s/vx300s_7_gripper"/>
                    <geom name="vx300s//unnamed_geom_13" class="vx300s/collision" pos="-0.02 0 0" quat="1 0 0 1" mesh="vx300s/vx300s_7_gripper"/>
                    <geom name="vx300s//unnamed_geom_14" class="vx300s/visual" pos="-0.020174999999999998 0 0" quat="1 0 0 1" mesh="vx300s/vx300s_9_gripper_bar"/>
                    <geom name="vx300s//unnamed_geom_15" class="vx300s/collision" pos="-0.020174999999999998 0 0" quat="1 0 0 1" mesh="vx300s/vx300s_9_gripper_bar"/>
                    <site name="vx300s/pinch" group="5" rgba="0.59999999999999998 0.29999999999999999 0.29999999999999999 1" size="0.0050000000000000001" pos="0.10000000000000001 0 0"/>
                    <body name="vx300s/gripper_prop_link" pos="0.048500000000000001 0 0">
                      <inertial pos="0.0023779999999999999 2.85e-08 0" quat="0 0 0.897698 0.44061099999999997" mass="0.0080090000000000005" diaginertia="4.2979e-06 2.8868e-06 1.5314000000000001e-06"/>
                      <geom name="vx300s//unnamed_geom_16" class="vx300s/visual" pos="-0.068500000000000005 0 0" quat="1 0 0 1" mesh="vx300s/vx300s_8_gripper_prop"/>
                      <geom name="vx300s//unnamed_geom_17" class="vx300s/collision" pos="-0.068500000000000005 0 0" quat="1 0 0 1" mesh="vx300s/vx300s_8_gripper_prop"/>
                    </body>
                    <body name="vx300s/left_finger_link" pos="0.068699999999999997 0 0">
                      <inertial pos="0.017343999999999998 -0.0060692000000000003 0" quat="0.44936399999999999 0.44936399999999999 -0.54596 -0.54596" mass="0.034796000000000001" diaginertia="2.48003e-05 1.417e-05 1.2079700000000001e-05"/>
                      <joint name="vx300s/left_finger" class="vx300s/left_finger"/>
                      <geom name="vx300s//unnamed_geom_18" class="vx300s/visual" pos="-0.040399999999999998 -0.057500000000000002 0" quat="-1 1 -1 1" mesh="vx300s/vx300s_10_gripper_finger"/>
                      <geom name="vx300s/left_finger_pad_0" class="vx300s/finger_collision" type="box" size="0.01405 0.01405 0.001" pos="0.047800000000000002 -0.012500000000000001 0.0106" quat="0.65000000000000002 0.65000000000000002 -0.27000000000000002 0.27000000000000002"/>
                      <geom name="vx300s/left_finger_pad_1" class="vx300s/finger_collision" type="box" size="0.01405 0.01405 0.001" pos="0.047800000000000002 -0.012500000000000001 -0.0106" quat="0.65000000000000002 0.65000000000000002 -0.27000000000000002 0.27000000000000002"/>
                      <geom name="vx300s/left_finger_pad_2" class="vx300s/finger_collision" type="box" size="0.010580000000000001 0.010580000000000001 0.001" pos="0.057099999999999998 -0.012500000000000001 0" quat="1 1 0 0"/>
                      <geom name="vx300s/left_finger_pad_3" class="vx300s/finger_collision" type="box" size="0.01 0.010500000000000001 0.001" pos="0.0378 -0.012500000000000001 0" quat="1 1 0 0"/>
                      <geom name="vx300s/left_finger_pad_4" class="vx300s/finger_collision" type="box" size="0.014999999999999999 0.010500000000000001 0.001" pos="0.012800000000000001 -0.012500000000000001 0" quat="1 1 0 0"/>
                      <geom name="vx300s/left_finger_pad_5" class="vx300s/finger_collision" type="box" size="0.01 0.010500000000000001 0.001" pos="0.0378 -0.012500000000000001 0.02" quat="1 1 0 0"/>
                      <geom name="vx300s/left_finger_pad_6" class="vx300s/finger_collision" type="box" size="0.014999999999999999 0.010500000000000001 0.001" pos="0.012800000000000001 -0.012500000000000001 0.02" quat="1 1 0 0"/>
                      <geom name="vx300s/left_finger_pad_7" class="vx300s/finger_collision" type="box" size="0.01 0.010500000000000001 0.001" pos="0.0378 -0.012500000000000001 -0.02" quat="1 1 0 0"/>
                      <geom name="vx300s/left_finger_pad_8" class="vx300s/finger_collision" type="box" size="0.014999999999999999 0.010500000000000001 0.001" pos="0.012800000000000001 -0.012500000000000001 -0.02" quat="1 1 0 0"/>
                    </body>
                    <body name="vx300s/right_finger_link" pos="0.068699999999999997 0 0">
                      <inertial pos="0.017343999999999998 0.0060692000000000003 0" quat="0.44936999999999999 -0.44936999999999999 0.54595499999999997 -0.54595499999999997" mass="0.034796000000000001" diaginertia="2.48002e-05 1.417e-05 1.2079800000000001e-05"/>
                      <joint name="vx300s/right_finger" class="vx300s/right_finger"/>
                      <geom name="vx300s//unnamed_geom_28" class="vx300s/visual" pos="-0.040399999999999998 0.057500000000000002 0" quat="1 1 1 1" mesh="vx300s/vx300s_10_gripper_finger"/>
                      <geom name="vx300s/right_finger_pad_0" class="vx300s/finger_collision" type="box" size="0.01405 0.01405 0.001" pos="0.047800000000000002 0.012500000000000001 0.0106" quat="0.65000000000000002 0.65000000000000002 -0.27000000000000002 0.27000000000000002"/>
                      <geom name="vx300s/right_finger_pad_1" class="vx300s/finger_collision" type="box" size="0.01405 0.01405 0.001" pos="0.047800000000000002 0.012500000000000001 -0.0106" quat="0.65000000000000002 0.65000000000000002 -0.27000000000000002 0.27000000000000002"/>
                      <geom name="vx300s/right_finger_pad_2" class="vx300s/finger_collision" type="box" size="0.010580000000000001 0.010580000000000001 0.001" pos="0.057099999999999998 0.012500000000000001 0" quat="1 1 0 0"/>
                      <geom name="vx300s/right_finger_pad_3" class="vx300s/finger_collision" type="box" size="0.01 0.010500000000000001 0.001" pos="0.0378 0.012500000000000001 0" quat="1 1 0 0"/>
                      <geom name="vx300s/right_finger_pad_4" class="vx300s/finger_collision" type="box" size="0.014999999999999999 0.010500000000000001 0.001" pos="0.012800000000000001 0.012500000000000001 0" quat="1 1 0 0"/>
                      <geom name="vx300s/right_finger_pad_5" class="vx300s/finger_collision" type="box" size="0.01 0.010500000000000001 0.001" pos="0.0378 0.012500000000000001 0.02" quat="1 1 0 0"/>
                      <geom name="vx300s/right_finger_pad_6" class="vx300s/finger_collision" type="box" size="0.014999999999999999 0.010500000000000001 0.001" pos="0.012800000000000001 0.012500000000000001 0.02" quat="1 1 0 0"/>
                      <geom name="vx300s/right_finger_pad_7" class="vx300s/finger_collision" type="box" size="0.01 0.010500000000000001 0.001" pos="0.0378 0.012500000000000001 -0.02" quat="1 1 0 0"/>
                      <geom name="vx300s/right_finger_pad_8" class="vx300s/finger_collision" type="box" size="0.014999999999999999 0.010500000000000001 0.001" pos="0.012800000000000001 0.012500000000000001 -0.02" quat="1 1 0 0"/>
                    </body>
                  </body>
                </body>
              </body>
            </body>
          </body>
        </body>
      </body>
    </body>
  </worldbody>
  <contact>
    <exclude name="vx300s//unnamed_contact_0" body1="vx300s/base_link" body2="vx300s/shoulder_link"/>
  </contact>
  <equality>
    <joint name="vx300s//unnamed_equality_0" class="vx300s/" joint1="vx300s/left_finger" joint2="vx300s/right_finger" polycoef="0 -1 0 0 0"/>
  </equality>
  <actuator>
    <position name="vx300s/waist" class="vx300s/waist" joint="vx300s/waist"/>
    <position name="vx300s/shoulder" class="vx300s/shoulder" joint="vx300s/shoulder"/>
    <position name="vx300s/elbow" class="vx300s/elbow" joint="vx300s/elbow"/>
    <position name="vx300s/forearm_roll" class="vx300s/forearm_roll" joint="vx300s/forearm_roll"/>
    <position name="vx300s/wrist_angle" class="vx300s/wrist_angle" joint="vx300s/wrist_angle"/>
    <position name="vx300s/wrist_rotate" class="vx300s/wrist_rotate" joint="vx300s/wrist_rotate"/>
    <position name="vx300s/gripper" class="vx300s/finger" joint="vx300s/left_finger"/>
  </actuator>
  <keyframe>
    <key name="vx300s/home" qpos="0 -0.95999999999999996 1.1599999999999999 0 -0.29999999999999999 0 0.024 -0.024" ctrl="0 -0.95999999999999996 1.1599999999999999 0 -0.29999999999999999 0 0.024"/>
  </keyframe>
</mujoco>
